Workbook

Sheet Form Responses 2
A1: Timestamp | B1: Borrower Name | C1: Entry No. | D1: ISBN
A2: 45803.953 | B2: Lokesh | C2: 24A1EENB0062 | D2: 9780141184944
A3: 46072.691 | B3: Luv | C3: 24A1EENB0062 | D3: 9780141184944

Sheet active
A1: =IFERROR(__xludf.DUMMYFUNCTION("QUERY('Form Responses 2'!A:Z, ""SELECT A, B, C, D WHERE A IS NOT NULL"", 1)"),"Timestamp") -> Timestamp | B1: =IFERROR(__xludf.DUMMYFUNCTION("""COMPUTED_VALUE"""),"Borrower Name ") -> Borrower Name | C1: =IFERROR(__xludf.DUMMYFUNCTION("""COMPUTED_VALUE"""),"Entry No.") -> Entry No. | D1: =IFERROR(__xludf.DUMMYFUNCTION("""COMPUTED_VALUE"""),"ISBN") -> ISBN | E1: Book Title | F1: Status | G1: Issued Date | H1: Due Date | I1: Returned Date | J1: Overdue
A2: =IFERROR(__xludf.DUMMYFUNCTION("""COMPUTED_VALUE"""),45803.95333731482) -> 45803.953 | B2: =IFERROR(__xludf.DUMMYFUNCTION("""COMPUTED_VALUE"""),"Lokesh ") -> Lokesh | C2: =IFERROR(__xludf.DUMMYFUNCTION("""COMPUTED_VALUE"""),"24A1EENB0062 ") -> 24A1EENB0062 | D2: =IFERROR(__xludf.DUMMYFUNCTION("""COMPUTED_VALUE"""),9.780141184944E12) -> 9780141184944 | E2: =VLOOKUP(D2, BookDatabase!$A$2:$B$1000, 2, FALSE) -> Silent Spring (Penguin Modern Classics) -- Paperback / softback | F2: Returned On Time | G2: 45803 | H2: =IF(G2<>"", G2 + 7, "") -> 45810 | I2: 45803 | J2: =IF(AND(ISNUMBER(H2), TODAY()>H2), "Overdue", "") -> Overdue
A3: =IFERROR(__xludf.DUMMYFUNCTION("""COMPUTED_VALUE"""),46072.69053212963) -> 46072.691 | B3: =IFERROR(__xludf.DUMMYFUNCTION("""COMPUTED_VALUE"""),"Luv") -> Luv | C3: =IFERROR(__xludf.DUMMYFUNCTION("""COMPUTED_VALUE"""),"24A1EENB0062 ") -> 24A1EENB0062 | D3: =IFERROR(__xludf.DUMMYFUNCTION("""COMPUTED_VALUE"""),9.780141184944E12) -> 9780141184944 | E3: =VLOOKUP(D3, BookDatabase!$A$2:$B$1000, 2, FALSE) -> Silent Spring (Penguin Modern Classics) -- Paperback / softback | F3: Processed and Borrowed | H3: =IF(G3<>"", G3 + 7, "") | J3: =IF(AND(ISNUMBER(H3), TODAY()>H3), "Overdue", "")
E4: =VLOOKUP(D4, BookDatabase!$A$2:$B$1000, 2, FALSE) -> #N/A | F4: =IF(A4<>"","In Processing","") | H4: =IF(G4<>"", G4 + 7, "") | J4: =IF(AND(ISNUMBER(H4), TODAY()>H4), "Overdue", "")
E5: =VLOOKUP(D5, BookDatabase!$A$2:$B$1000, 2, FALSE) -> #N/A | F5: =IF(A5<>"","In Processing","") | H5: =IF(G5<>"", G5 + 7, "") | J5: =IF(AND(ISNUMBER(H5), TODAY()>H5), "Overdue", "")
E6: =VLOOKUP(D6, BookDatabase!$A$2:$B$1000, 2, FALSE) -> #N/A | F6: =IF(A6<>"","In Processing","") | H6: =IF(G6<>"", G6 + 7, "") | J6: =IF(AND(ISNUMBER(H6), TODAY()>H6), "Overdue", "")
E7: =VLOOKUP(D7, BookDatabase!$A$2:$B$1000, 2, FALSE) -> #N/A | F7: =IF(A7<>"","In Processing","") | H7: =IF(G7<>"", G7 + 7, "") | J7: =IF(AND(ISNUMBER(H7), TODAY()>H7), "Overdue", "")
E8: =VLOOKUP(D8, BookDatabase!$A$2:$B$1000, 2, FALSE) -> #N/A | F8: =IF(A8<>"","In Processing","") | H8: =IF(G8<>"", G8 + 7, "") | J8: =IF(AND(ISNUMBER(H8), TODAY()>H8), "Overdue", "")
E9: =VLOOKUP(D9, BookDatabase!$A$2:$B$1000, 2, FALSE) -> #N/A | F9: =IF(A9<>"","In Processing","") | H9: =IF(G9<>"", G9 + 7, "") | J9: =IF(AND(ISNUMBER(H9), TODAY()>H9), "Overdue", "")
E10: =VLOOKUP(D10, BookDatabase!$A$2:$B$1000, 2, FALSE) -> #N/A | F10: =IF(A10<>"","In Processing","") | H10: =IF(G10<>"", G10 + 7, "") | J10: =IF(AND(ISNUMBER(H10), TODAY()>H10), "Overdue", "")
E11: =VLOOKUP(D11, BookDatabase!$A$2:$B$1000, 2, FALSE) -> #N/A | F11: =IF(A11<>"","In Processing","") | H11: =IF(G11<>"", G11 + 7, "") | J11: =IF(AND(ISNUMBER(H11), TODAY()>H11), "Overdue", "")
E12: =VLOOKUP(D12, BookDatabase!$A$2:$B$1000, 2, FALSE) -> #N/A | F12: =IF(A12<>"","In Processing","") | H12: =IF(G12<>"", G12 + 7, "") | J12: =IF(AND(ISNUMBER(H12), TODAY()>H12), "Overdue", "")
E13: =VLOOKUP(D13, BookDatabase!$A$2:$B$1000, 2, FALSE) -> #N/A | F13: =IF(A13<>"","In Processing","") | H13: =IF(G13<>"", G13 + 7, "") | J13: =IF(AND(ISNUMBER(H13), TODAY()>H13), "Overdue", "")
E14: =VLOOKUP(D14, BookDatabase!$A$2:$B$1000, 2, FALSE) -> #N/A | F14: =IF(A14<>"","In Processing","") | H14: =IF(G14<>"", G14 + 7, "") | J14: =IF(AND(ISNUMBER(H14), TODAY()>H14), "Overdue", "")
E15: =VLOOKUP(D15, BookDatabase!$A$2:$B$1000, 2, FALSE) -> #N/A | F15: =IF(A15<>"","In Processing","") | H15: =IF(G15<>"", G15 + 7, "") | J15: =IF(AND(ISNUMBER(H15), TODAY()>H15), "Overdue", "")
... E235: =VLOOKUP(D235, BookDatabase!$A$2:$B$1000, 2, FALSE) -> #N/A | F235: =IF(A235<>"","In Processing","") | H235: =IF(G235<>"", G235 + 7, "") | J235: =IF(AND(ISNUMBER(H235), TODAY()>H235), "Overdue", "")

Sheet BookTracker
A1: ISBN | B1: Book Title | C1: Author | D1: Quantity | E1: Borrowed | F1: Status | G1: Expected Availability
A2: 9780141184944 | B2: Silent Spring (Penguin Modern Classics) -- Paperback / softback | C2: Rachel Carson | D2: 4 | E2: =IF( COUNTIFS(active!D:D, A2, active!F:F, "Processed and Borrowed") > D2, "Error", COUNTIFS(active!D:D, A2, active!F:F, "Processed and Borrowed") ) -> 1 | F2: =IF(E2 < D2, "Available", "Not Available") -> Available | G2: =IFERROR(__xludf.DUMMYFUNCTION("IF(E2>0, MIN(FILTER(active!H:H, (active!D:D = A2) * (active!F:F = ""Processed and Borrowed""))), """")"),0.0) -> 0
A3: 9780393609394 | B3: Astrophysics for People in a Hurry | C3: Neil deGrasse Tyson | D3: 3 | E3: =IF( COUNTIFS(active!D:D, A3, active!F:F, "Processed and Borrowed") > D3, "Error", COUNTIFS(active!D:D, A3, active!F:F, "Processed and Borrowed") ) -> 0 | F3: =IF(E3 < D3, "Available", "Not Available") -> Available | G3: =IFERROR(__xludf.DUMMYFUNCTION("IF(E3>0, MIN(FILTER(active!H:H, (active!D:D = A3) * (active!F:F = ""Processed and Borrowed""))), """")"),"")
A4: 9780099590088 | B4: Sapiens : The Multi-million Copy Bestseller -- Paperback / softback | C4: Yuval Noah Harari | D4: 3 | E4: =IF( COUNTIFS(active!D:D, A4, active!F:F, "Processed and Borrowed") > D4, "Error", COUNTIFS(active!D:D, A4, active!F:F, "Processed and Borrowed") ) -> 0 | F4: =IF(E4 < D4, "Available", "Not Available") -> Available | G4: =IFERROR(__xludf.DUMMYFUNCTION("IF(E4>0, MIN(FILTER(active!H:H, (active!D:D = A4) * (active!F:F = ""Processed and Borrowed""))), """")"),"")
A5: 9780241958223 | B5: Start with Why : How Great Leaders Inspire Everyone to Take Action -- Paperback / softback | C5: Simon Sinek | D5: 3 | E5: =IF( COUNTIFS(active!D:D, A5, active!F:F, "Processed and Borrowed") > D5, "Error", COUNTIFS(active!D:D, A5, active!F:F, "Processed and Borrowed") ) -> 0 | F5: =IF(E5 < D5, "Available", "Not Available") -> Available | G5: =IFERROR(__xludf.DUMMYFUNCTION("IF(E5>0, MIN(FILTER(active!H:H, (active!D:D = A5) * (active!F:F = ""Processed and Borrowed""))), """")"),"")
A6: 9781509877027 | B6: Immortal Life of Henrietta Lacks (Picador Classic) -- Paperback / softback | C6: Rebecca Skloot | D6: 3 | E6: =IF( COUNTIFS(active!D:D, A6, active!F:F, "Processed and Borrowed") > D6, "Error", COUNTIFS(active!D:D, A6, active!F:F, "Processed and Borrowed") ) -> 0 | F6: =IF(E6 < D6, "Available", "Not Available") -> Available | G6: =IFERROR(__xludf.DUMMYFUNCTION("IF(E6>0, MIN(FILTER(active!H:H, (active!D:D = A6) * (active!F:F = ""Processed and Borrowed""))), """")"),"")
A7: 9780340733509 | B7: Power of Now : (20th Anniversary Edition) (The Power of Now) -- Paperback / softback | C7: Eckhart Tolle | D7: 3 | E7: =IF( COUNTIFS(active!D:D, A7, active!F:F, "Processed and Borrowed") > D7, "Error", COUNTIFS(active!D:D, A7, active!F:F, "Processed and Borrowed") ) -> 0 | F7: =IF(E7 < D7, "Available", "Not Available") -> Available | G7: =IFERROR(__xludf.DUMMYFUNCTION("IF(E7>0, MIN(FILTER(active!H:H, (active!D:D = A7) * (active!F:F = ""Processed and Borrowed""))), """")"),"")
A8: 9780141983769 | B8: Why We Sleep : The New Science of Sleep and Dreams -- Paperback / softback | C8: Matthew Walker | D8: 3 | E8: =IF( COUNTIFS(active!D:D, A8, active!F:F, "Processed and Borrowed") > D8, "Error", COUNTIFS(active!D:D, A8, active!F:F, "Processed and Borrowed") ) -> 0 | F8: =IF(E8 < D8, "Available", "Not Available") -> Available | G8: =IFERROR(__xludf.DUMMYFUNCTION("IF(E8>0, MIN(FILTER(active!H:H, (active!D:D = A8) * (active!F:F = ""Processed and Borrowed""))), """")"),"")
A9: 9780349107035 | B9: Cosmos | C9: Carl Sagan | D9: 3 | E9: =IF( COUNTIFS(active!D:D, A9, active!F:F, "Processed and Borrowed") > D9, "Error", COUNTIFS(active!D:D, A9, active!F:F, "Processed and Borrowed") ) -> 0 | F9: =IF(E9 < D9, "Available", "Not Available") -> Available | G9: =IFERROR(__xludf.DUMMYFUNCTION("IF(E9>0, MIN(FILTER(active!H:H, (active!D:D = A9) * (active!F:F = ""Processed and Borrowed""))), """")"),"")
A10: 9780340960196 | B10: Dune -- Paperback | C10: Frank Herbert | D10: 3 | E10: =IF( COUNTIFS(active!D:D, A10, active!F:F, "Processed and Borrowed") > D10, "Error", COUNTIFS(active!D:D, A10, active!F:F, "Processed and Borrowed") ) -> 0 | F10: =IF(E10 < D10, "Available", "Not Available") -> Available | G10: =IFERROR(__xludf.DUMMYFUNCTION("IF(E10>0, MIN(FILTER(active!H:H, (active!D:D = A10) * (active!F:F = ""Processed and Borrowed""))), """")"),"")
A11: 9780753828434 | B11: Double Helix -- Paperback / softback | C11: James D. Watson | D11: 3 | E11: =IF( COUNTIFS(active!D:D, A11, active!F:F, "Processed and Borrowed") > D11, "Error", COUNTIFS(active!D:D, A11, active!F:F, "Processed and Borrowed") ) -> 0 | F11: =IF(E11 < D11, "Available", "Not Available") -> Available | G11: =IFERROR(__xludf.DUMMYFUNCTION("IF(E11>0, MIN(FILTER(active!H:H, (active!D:D = A11) * (active!F:F = ""Processed and Borrowed""))), """")"),"")
A12: 9780857501004 | B12: A Brief History Of Time : From Big Bang To Black Holes | C12: Stephen Hawking | D12: 3 | E12: =IF( COUNTIFS(active!D:D, A12, active!F:F, "Processed and Borrowed") > D12, "Error", COUNTIFS(active!D:D, A12, active!F:F, "Processed and Borrowed") ) -> 0 | F12: =IF(E12 < D12, "Available", "Not Available") -> Available | G12: =IFERROR(__xludf.DUMMYFUNCTION("IF(E12>0, MIN(FILTER(active!H:H, (active!D:D = A12) * (active!F:F = ""Processed and Borrowed""))), """")"),"")
A13: 9781847941831 | B13: Atomic Habits | C13: James Clear | D13: 3 | E13: =IF( COUNTIFS(active!D:D, A13, active!F:F, "Processed and Borrowed") > D13, "Error", COUNTIFS(active!D:D, A13, active!F:F, "Processed and Borrowed") ) -> 0 | F13: =IF(E13 < D13, "Available", "Not Available") -> Available | G13: =IFERROR(__xludf.DUMMYFUNCTION("IF(E13>0, MIN(FILTER(active!H:H, (active!D:D = A13) * (active!F:F = ""Processed and Borrowed""))), """")"),"")
A14: 9780099477464 | B14: Brave New World | C14: Aldous Huxley | D14: 3 | E14: =IF( COUNTIFS(active!D:D, A14, active!F:F, "Processed and Borrowed") > D14, "Error", COUNTIFS(active!D:D, A14, active!F:F, "Processed and Borrowed") ) -> 0 | F14: =IF(E14 < D14, "Available", "Not Available") -> Available | G14: =IFERROR(__xludf.DUMMYFUNCTION("IF(E14>0, MIN(FILTER(active!H:H, (active!D:D = A14) * (active!F:F = ""Processed and Borrowed""))), """")"),"")
A15: 9781844132393 | B15: Man's Search for Meaning : The classic tribute to hope from the Holocaust -- Paperback / softback | C15: Viktor E. Frankl | D15: 3 | E15: =IF( COUNTIFS(active!D:D, A15, active!F:F, "Processed and Borrowed") > D15, "Error", COUNTIFS(active!D:D, A15, active!F:F, "Processed and Borrowed") ) -> 0 | F15: =IF(E15 < D15, "Available", "Not Available") -> Available | G15: =IFERROR(__xludf.DUMMYFUNCTION("IF(E15>0, MIN(FILTER(active!H:H, (active!D:D = A15) * (active!F:F = ""Processed and Borrowed""))), """")"),"")
A16: 9780099289920 | B16: Elegant Universe -- Paperback / softback | C16: Brian Greene | D16: 3 | E16: =IF( COUNTIFS(active!D:D, A16, active!F:F, "Processed and Borrowed") > D16, "Error", COUNTIFS(active!D:D, A16, active!F:F, "Processed and Borrowed") ) -> 0 | F16: =IF(E16 < D16, "Available", "Not Available") -> Available | G16: =IFERROR(__xludf.DUMMYFUNCTION("IF(E16>0, MIN(FILTER(active!H:H, (active!D:D = A16) * (active!F:F = ""Processed and Borrowed""))), """")"),"")
A17: 9780007250929 | B17: Emperor of All Maladies -- Paperback / softback | C17: Siddhartha Mukherjee | D17: 3 | E17: =IF( COUNTIFS(active!D:D, A17, active!F:F, "Processed and Borrowed") > D17, "Error", COUNTIFS(active!D:D, A17, active!F:F, "Processed and Borrowed") ) -> 0 | F17: =IF(E17 < D17, "Available", "Not Available") -> Available | G17: =IFERROR(__xludf.DUMMYFUNCTION("IF(E17>0, MIN(FILTER(active!H:H, (active!D:D = A17) * (active!F:F = ""Processed and Borrowed""))), """")"),"")
A18: 9780099584575 | B18: Gene : An Intimate History -- Paperback / softback | C18: Siddhartha Mukherjee | D18: 3 | E18: =IF( COUNTIFS(active!D:D, A18, active!F:F, "Processed and Borrowed") > D18, "Error", COUNTIFS(active!D:D, A18, active!F:F, "Processed and Borrowed") ) -> 0 | F18: =IF(E18 < D18, "Available", "Not Available") -> Available | G18: =IFERROR(__xludf.DUMMYFUNCTION("IF(E18>0, MIN(FILTER(active!H:H, (active!D:D = A18) * (active!F:F = ""Processed and Borrowed""))), """")"),"")
A19: 9781405931564 | B19: Big Little Lies | C19: Liane Moriarty | D19: 2 | E19: =IF( COUNTIFS(active!D:D, A19, active!F:F, "Processed and Borrowed") > D19, "Error", COUNTIFS(active!D:D, A19, active!F:F, "Processed and Borrowed") ) -> 0 | F19: =IF(E19 < D19, "Available", "Not Available") -> Available | G19: =IFERROR(__xludf.DUMMYFUNCTION("IF(E19>0, MIN(FILTER(active!H:H, (active!D:D = A19) * (active!F:F = ""Processed and Borrowed""))), """")"),"")
A20: 9781857028355 | B20: Genome : The Autobiography of a Species in 23 Chapters -- Paperback / softback | C20: Matt Ridley | D20: 2 | E20: =IF( COUNTIFS(active!D:D, A20, active!F:F, "Processed and Borrowed") > D20, "Error", COUNTIFS(active!D:D, A20, active!F:F, "Processed and Borrowed") ) -> 0 | F20: =IF(E20 < D20, "Available", "Not Available") -> Available | G20: =IFERROR(__xludf.DUMMYFUNCTION("IF(E20>0, MIN(FILTER(active!H:H, (active!D:D = A20) * (active!F:F = ""Processed and Borrowed""))), """")"),"")
A21: 9780345409461 | B21: The Demon-Haunted World | C21: Carl Sagan | D21: 2 | E21: =IF( COUNTIFS(active!D:D, A21, active!F:F, "Processed and Borrowed") > D21, "Error", COUNTIFS(active!D:D, A21, active!F:F, "Processed and Borrowed") ) -> 0 | F21: =IF(E21 < D21, "Available", "Not Available") -> Available | G21: =IFERROR(__xludf.DUMMYFUNCTION("IF(E21>0, MIN(FILTER(active!H:H, (active!D:D = A21) * (active!F:F = ""Processed and Borrowed""))), """")"),"")
A22: 9780876120798 | B22: Autobiography of a Yogi | C22: Paramahansa Yogananda | D22: 2 | E22: =IF( COUNTIFS(active!D:D, A22, active!F:F, "Processed and Borrowed") > D22, "Error", COUNTIFS(active!D:D, A22, active!F:F, "Processed and Borrowed") ) -> 0 | F22: =IF(E22 < D22, "Available", "Not Available") -> Available | G22: =IFERROR(__xludf.DUMMYFUNCTION("IF(E22>0, MIN(FILTER(active!H:H, (active!D:D = A22) * (active!F:F = ""Processed and Borrowed""))), """")"),"")
A23: 9781526604750 | B23: A Thousand Splendid Suns | C23: Khaled Hosseini | D23: 2 | E23: =IF( COUNTIFS(active!D:D, A23, active!F:F, "Processed and Borrowed") > D23, "Error", COUNTIFS(active!D:D, A23, active!F:F, "Processed and Borrowed") ) -> 0 | F23: =IF(E23 < D23, "Available", "Not Available") -> Available | G23: =IFERROR(__xludf.DUMMYFUNCTION("IF(E23>0, MIN(FILTER(active!H:H, (active!D:D = A23) * (active!F:F = ""Processed and Borrowed""))), """")"),"")
A24: 9781800244399 | B24: Alexander Hamilton -- Paperback / softback | C24: Ron Chernow | D24: 2 | E24: =IF( COUNTIFS(active!D:D, A24, active!F:F, "Processed and Borrowed") > D24, "Error", COUNTIFS(active!D:D, A24, active!F:F, "Processed and Borrowed") ) -> 0 | F24: =IF(E24 < D24, "Available", "Not Available") -> Available | G24: =IFERROR(__xludf.DUMMYFUNCTION("IF(E24>0, MIN(FILTER(active!H:H, (active!D:D = A24) * (active!F:F = ""Processed and Borrowed""))), """")"),"")
A25: 9781786891686 | B25: Life Of Pi | C25: Yann Martel | D25: 2 | E25: =IF( COUNTIFS(active!D:D, A25, active!F:F, "Processed and Borrowed") > D25, "Error", COUNTIFS(active!D:D, A25, active!F:F, "Processed and Borrowed") ) -> 0 | F25: =IF(E25 < D25, "Available", "Not Available") -> Available | G25: =IFERROR(__xludf.DUMMYFUNCTION("IF(E25>0, MIN(FILTER(active!H:H, (active!D:D = A25) * (active!F:F = ""Processed and Borrowed""))), """")"),"")
A26: 9781408851241 | B26: Sixth Extinction : An Unnatural History -- Paperback | C26: Elizabeth Kolbert | D26: 2 | E26: =IF( COUNTIFS(active!D:D, A26, active!F:F, "Processed and Borrowed") > D26, "Error", COUNTIFS(active!D:D, A26, active!F:F, "Processed and Borrowed") ) -> 0 | F26: =IF(E26 < D26, "Available", "Not Available") -> Available | G26: =IFERROR(__xludf.DUMMYFUNCTION("IF(E26>0, MIN(FILTER(active!H:H, (active!D:D = A26) * (active!F:F = ""Processed and Borrowed""))), """")"),"")
A27: 9780141199702 | B27: A Tale of Two Cities | C27: Charles Dickens | D27: 2 | E27: =IF( COUNTIFS(active!D:D, A27, active!F:F, "Processed and Borrowed") > D27, "Error", COUNTIFS(active!D:D, A27, active!F:F, "Processed and Borrowed") ) -> 0 | F27: =IF(E27 < D27, "Available", "Not Available") -> Available | G27: =IFERROR(__xludf.DUMMYFUNCTION("IF(E27>0, MIN(FILTER(active!H:H, (active!D:D = A27) * (active!F:F = ""Processed and Borrowed""))), """")"),"")
A28: 9780241982976 | B28: Becoming : The No. 1 International Bestseller -- Paperback / softback | C28: Michelle Obama | D28: 2 | E28: =IF( COUNTIFS(active!D:D, A28, active!F:F, "Processed and Borrowed") > D28, "Error", COUNTIFS(active!D:D, A28, active!F:F, "Processed and Borrowed") ) -> 0 | F28: =IF(E28 < D28, "Available", "Not Available") -> Available | G28: =IFERROR(__xludf.DUMMYFUNCTION("IF(E28>0, MIN(FILTER(active!H:H, (active!D:D = A28) * (active!F:F = ""Processed and Borrowed""))), """")"),"")
A29: 9780140449136 | B29: Crime and Punishment | C29: Fyodor Dostoevsky | D29: 2 | E29: =IF( COUNTIFS(active!D:D, A29, active!F:F, "Processed and Borrowed") > D29, "Error", COUNTIFS(active!D:D, A29, active!F:F, "Processed and Borrowed") ) -> 0 | F29: =IF(E29 < D29, "Available", "Not Available") -> Available | G29: =IFERROR(__xludf.DUMMYFUNCTION("IF(E29>0, MIN(FILTER(active!H:H, (active!D:D = A29) * (active!F:F = ""Processed and Borrowed""))), """")"),"")
A30: 9780670923175 | B30: Leaders Eat Last | C30: Simon Sinek | D30: 2 | E30: =IF( COUNTIFS(active!D:D, A30, active!F:F, "Processed and Borrowed") > D30, "Error", COUNTIFS(active!D:D, A30, active!F:F, "Processed and Borrowed") ) -> 0 | F30: =IF(E30 < D30, "Available", "Not Available") -> Available | G30: =IFERROR(__xludf.DUMMYFUNCTION("IF(E30>0, MIN(FILTER(active!H:H, (active!D:D = A30) * (active!F:F = ""Processed and Borrowed""))), """")"),"")
A31: 9780140449334 | B31: Meditations | C31: Marcus Aurelius | D31: 2 | E31: =IF( COUNTIFS(active!D:D, A31, active!F:F, "Processed and Borrowed") > D31, "Error", COUNTIFS(active!D:D, A31, active!F:F, "Processed and Borrowed") ) -> 0 | F31: =IF(E31 < D31, "Available", "Not Available") -> Available | G31: =IFERROR(__xludf.DUMMYFUNCTION("IF(E31>0, MIN(FILTER(active!H:H, (active!D:D = A31) * (active!F:F = ""Processed and Borrowed""))), """")"),"")
A32: 9781529038347 | B32: Radical Candor : Fully Revised and Updated Edition: How to Get What You Want by Saying What You M -- Paperback / softback | C32: Kim Scott | D32: 2 | E32: =IF( COUNTIFS(active!D:D, A32, active!F:F, "Processed and Borrowed") > D32, "Error", COUNTIFS(active!D:D, A32, active!F:F, "Processed and Borrowed") ) -> 0 | F32: =IF(E32 < D32, "Available", "Not Available") -> Available | G32: =IFERROR(__xludf.DUMMYFUNCTION("IF(E32>0, MIN(FILTER(active!H:H, (active!D:D = A32) * (active!F:F = ""Processed and Borrowed""))), """")"),"")
A33: 9780141981727 | B33: Seven Brief Lessons on Physics -- Paperback / softback (English Language Edition) | C33: Carlo Rovelli | D33: 2 | E33: =IF( COUNTIFS(active!D:D, A33, active!F:F, "Processed and Borrowed") > D33, "Error", COUNTIFS(active!D:D, A33, active!F:F, "Processed and Borrowed") ) -> 0 | F33: =IF(E33 < D33, "Available", "Not Available") -> Available | G33: =IFERROR(__xludf.DUMMYFUNCTION("IF(E33>0, MIN(FILTER(active!H:H, (active!D:D = A33) * (active!F:F = ""Processed and Borrowed""))), """")"),"")
A34: 9781471146725 | B34: Shoe Dog : A Memoir by the Creator of Nike -- Paperback / softback | C34: Phil Knight | D34: 2 | E34: =IF( COUNTIFS(active!D:D, A34, active!F:F, "Processed and Borrowed") > D34, "Error", COUNTIFS(active!D:D, A34, active!F:F, "Processed and Borrowed") ) -> 0 | F34: =IF(E34 < D34, "Available", "Not Available") -> Available | G34: =IFERROR(__xludf.DUMMYFUNCTION("IF(E34>0, MIN(FILTER(active!H:H, (active!D:D = A34) * (active!F:F = ""Processed and Borrowed""))), """")"),"")
A35: 9780241953181 | B35: Snow Crash -- Paperback / softback | C35: Neal Stephenson | D35: 2 | E35: =IF( COUNTIFS(active!D:D, A35, active!F:F, "Processed and Borrowed") > D35, "Error", COUNTIFS(active!D:D, A35, active!F:F, "Processed and Borrowed") ) -> 0 | F35: =IF(E35 < D35, "Available", "Not Available") -> Available | G35: =IFERROR(__xludf.DUMMYFUNCTION("IF(E35>0, MIN(FILTER(active!H:H, (active!D:D = A35) * (active!F:F = ""Processed and Borrowed""))), """")"),"")
A36: 9781471195204 | B36: 7 Habits of Highly Effective People: Revised and Updated : 30th Anniversary Edition -- Paperback / softback | C36: Stephen R. Covey | D36: 2 | E36: =IF( COUNTIFS(active!D:D, A36, active!F:F, "Processed and Borrowed") > D36, "Error", COUNTIFS(active!D:D, A36, active!F:F, "Processed and Borrowed") ) -> 0 | F36: =IF(E36 < D36, "Available", "Not Available") -> Available | G36: =IFERROR(__xludf.DUMMYFUNCTION("IF(E36>0, MIN(FILTER(active!H:H, (active!D:D = A36) * (active!F:F = ""Processed and Borrowed""))), """")"),"")
A37: 9780722532935 | B37: Alchemist -- Paperback / softback (English Language Edition) | C37: Paulo Coelho | D37: 2 | E37: =IF( COUNTIFS(active!D:D, A37, active!F:F, "Processed and Borrowed") > D37, "Error", COUNTIFS(active!D:D, A37, active!F:F, "Processed and Borrowed") ) -> 0 | F37: =IF(E37 < D37, "Available", "Not Available") -> Available | G37: =IFERROR(__xludf.DUMMYFUNCTION("IF(E37>0, MIN(FILTER(active!H:H, (active!D:D = A37) * (active!F:F = ""Processed and Borrowed""))), """")"),"")
A38: 9780143105756 | B38: The Art of War | C38: Sun Tzu | D38: 2 | E38: =IF( COUNTIFS(active!D:D, A38, active!F:F, "Processed and Borrowed") > D38, "Error", COUNTIFS(active!D:D, A38, active!F:F, "Processed and Borrowed") ) -> 0 | F38: =IF(E38 < D38, "Available", "Not Available") -> Available | G38: =IFERROR(__xludf.DUMMYFUNCTION("IF(E38>0, MIN(FILTER(active!H:H, (active!D:D = A38) * (active!F:F = ""Processed and Borrowed""))), """")"),"")
A39: 9781784162122 | B39: The Book Thief | C39: Markus Zusak | D39: 2 | E39: =IF( COUNTIFS(active!D:D, A39, active!F:F, "Processed and Borrowed") > D39, "Error", COUNTIFS(active!D:D, A39, active!F:F, "Processed and Borrowed") ) -> 0 | F39: =IF(E39 < D39, "Available", "Not Available") -> Available | G39: =IFERROR(__xludf.DUMMYFUNCTION("IF(E39>0, MIN(FILTER(active!H:H, (active!D:D = A39) * (active!F:F = ""Processed and Borrowed""))), """")"),"")
A40: 9780141315188 | B40: Diary of a Young Girl -- Paperback / softback (English Language Edition) | C40: Anne Frank | D40: 2 | E40: =IF( COUNTIFS(active!D:D, A40, active!F:F, "Processed and Borrowed") > D40, "Error", COUNTIFS(active!D:D, A40, active!F:F, "Processed and Borrowed") ) -> 0 | F40: =IF(E40 < D40, "Available", "Not Available") -> Available | G40: =IFERROR(__xludf.DUMMYFUNCTION("IF(E40>0, MIN(FILTER(active!H:H, (active!D:D = A40) * (active!F:F = ""Processed and Borrowed""))), """")"),"")
...

Sheet BookDatabase
A1: ISBN | B1: Book Title | C1: Author
A2: 9780141184944 | B2: Silent Spring (Penguin Modern Classics) -- Paperback / softback | C2: Rachel Carson
A3: 9780393609394 | B3: Astrophysics for People in a Hurry | C3: Neil deGrasse Tyson
A4: 9780099590088 | B4: Sapiens : The Multi-million Copy Bestseller -- Paperback / softback | C4: Yuval Noah Harari
A5: 9780241958223 | B5: Start with Why : How Great Leaders Inspire Everyone to Take Action -- Paperback / softback | C5: Simon Sinek
A6: 9781509877027 | B6: Immortal Life of Henrietta Lacks (Picador Classic) -- Paperback / softback | C6: Rebecca Skloot
A7: 9780340733509 | B7: Power of Now : (20th Anniversary Edition) (The Power of Now) -- Paperback / softback | C7: Eckhart Tolle
A8: 9780141983769 | B8: Why We Sleep : The New Science of Sleep and Dreams -- Paperback / softback | C8: Matthew Walker
A9: 9780349107035 | B9: Cosmos | C9: Carl Sagan
A10: 9780340960196 | B10: Dune -- Paperback | C10: Frank Herbert
A11: 9780753828434 | B11: Double Helix -- Paperback / softback | C11: James D. Watson
A12: 9780857501004 | B12: A Brief History Of Time : From Big Bang To Black Holes | C12: Stephen Hawking
A13: 9781847941831 | B13: Atomic Habits | C13: James Clear
... A355: 9780691165851 | B355: Lost Enlightenment | C355: Christopher L. C. E.
